Workbook

Sheet Instrucciones
B1: CONTROL OPERATIVO Y FINANCIERO · TALLER DE MANTENCIÓN Y REPARACIÓN DE BUSES
B2: Prototipo de portafolio · todos los datos son sintéticos y no corresponden a clientes reales
B4: 1. PROPÓSITO | C4: Entregar a la gerencia de una pyme de mantención de buses una vista mensual de la operación (plazos, carga de trabajo, OT atrasadas) y de la rentabilidad (cobrable, costos directos y margen de contribución), y servir como muestra de modelamiento de datos y analítica de procesos.
B5: 2. ESTRUCTURA DE HOJAS | C5: Instrucciones: esta hoja. Maestro_Clientes (T_Clientes), Maestro_Tecnicos (T_Tecnicos), Maestro_Repuestos (T_Repuestos): catálogos de referencia. Registro_OT (T_OrdenesTrabajo): una fila por orden de trabajo; incluye columnas calculadas (encabezado gris) que alimentan el Dashboard. Detalle_OT (T_DetalleOT): líneas de repuestos y mano de obra de cada OT; de aquí salen costos y precios. Dashboard: KPI, Top 5 de repuestos, alertas y gráficos. Pruebas_Verificacion: matriz de pruebas con resultado esperado vs obtenido.
B6: 3. CÓDIGO DE COLORES | C6: Texto azul sobre fondo amarillo claro: celdas que el usuario puede cambiar (filtros y fecha de corte del Dashboard). Encabezados azul oscuro: datos que se ingresan. Encabezados gris: columnas con fórmulas, no editar. Semáforo: rojo = crítico o margen negativo, ámbar = atención o margen bajo (menor a 15%), verde = saludable.
B7: 4. USO DEL DASHBOARD | C7: Elegir Mes de ingreso, Tipo de servicio y Estado de OT en las celdas amarillas (listas desplegables). Los KPI, el Top 5 y los gráficos se recalculan. Las alertas son siempre globales. Nota sobre segmentadores: este archivo usa listas desplegables porque la librería con que se generó no puede crear segmentadores nativos. Si se desean, en Excel: clic en la tabla T_OrdenesTrabajo > Insertar > Segmentación de datos.
B8: 5. ACTUALIZACIÓN MENSUAL | C8: 1) Agregar las nuevas OT al final de Registro_OT (la tabla se expande sola) y sus líneas al final de Detalle_OT. Completar solo las columnas con encabezado azul oscuro. 2) Copiar hacia abajo las fórmulas de las columnas de encabezado gris desde la última fila existente. 3) Si aparece un mes nuevo, agregarlo a la lista del filtro «Mes de ingreso» y a la tabla de apoyo de gráficos (columna O del Dashboard, a la derecha). 4) Cambiar la fecha de corte del Dashboard (o reemplazarla por =HOY()). 5) Revisar la hoja Pruebas_Verificacion: los valores esperados corresponden a los datos de ejemplo y deben ignorarse o recalcularse al cargar datos reales.
B9: 6. REGLAS DEL MODELO | C9: Margen de contribución = Importe cobrable − (Costo materiales + Costo mano de obra). OT abierta: estado En Curso o Reprogramada. OT atrasada activa: abierta con fecha de compromiso anterior a la fecha de corte. Cumplimiento de plazos: OT con fecha de término menor o igual a la fecha de compromiso, sobre el total de OT con término. Una línea de detalle sin costo o sin precio se valora en cero y se marca en Alerta_Dato para que no pase inadvertida.
B10: 7. LIMITACIONES | C10: Es un prototipo de control operativo y financiero, no un ERP contable: no maneja inventario, IVA, costos indirectos, remuneraciones reales ni conciliación bancaria. Los costos de mano de obra se ingresan como costo por hora por línea; no se calculan desde liquidaciones. Las fórmulas usan INDEX/MATCH en lugar de BUSCARX para mantener compatibilidad con versiones anteriores de Excel. Los datos son sintéticos: las cifras ilustran el funcionamiento del modelo, no un negocio real.
B11: 8. EJEMPLO DE LECTURA | C11: Un margen en rojo en Registro_OT indica una OT cobrada bajo su costo (descuento, garantía o precio mal cargado). Revisar primero las OT con marca de dato incompleto, porque un precio faltante deprime artificialmente el margen.

Sheet Control_Mandante
B1: DASHBOARD DE CUADRE Y TRIANGULACIÓN · PRESUPUESTO - OC - FACTURA
B2: Auditoría de Descuadres entre Presupuesto de Taller, Orden de Compra de la Mandante y Factura Emitida
B4: Filtro Mes: | C4: Todos | E4: Filtro Cliente: | F4: Todos | H4: Filtro Cuadre: | I4: Todos | K4: Filtro Mecánico: | L4: Todos
B6: 1. VOLUMEN DE DOCUMENTOS Y ESTADO DE CUADRE (SEGÚN FILTROS SELECCIONADOS)
B7: TOTAL PRESUPUESTOS | E7: PRESUPUESTOS APROBADOS | H7: OCs RECIBIDAS MANDANTE | K7: OPERACIONES CUADRADAS | N7: DESCUADRES DETECTADOS
B8: =COUNTIFS(Registro_OT!$AM$2:$AM$181, 1) -> 180 | E8: =COUNTIFS(Registro_OT!$AM$2:$AM$181, 1, Registro_OT!$M$2:$M$181, "Aprobado") -> 177 | H8: =COUNTIFS(Registro_OT!$AM$2:$AM$181, 1, Registro_OT!$Q$2:$Q$181, "Recibida") -> 173 | K8: =COUNTIFS(Registro_OT!$AM$2:$AM$181, 1, Registro_OT!$W$2:$W$181, "CUADRADO (3-WAY OK)") -> 153 | N8: =COUNTIFS(Registro_OT!$AM$2:$AM$181, 1, Registro_OT!$W$2:$W$181, "DESCUADRE DE MONTOS") -> 1
B10: 2. MONTO FINANCIERO TOTAL ($) (PRESUPUESTADO vs. OC MANDANTE vs. FACTURADO)
B11: MONTO PRESUPUESTADO ($) | E11: MONTO OC MANDANTE ($) | H11: MONTO FACTURADO ($) | K11: GAP PRESUPUESTO vs. OC ($) | N11: PENDIENTE FACTURAR ($)
B12: =SUMIFS(Registro_OT!$L$2:$L$181, Registro_OT!$AM$2:$AM$181, 1) -> 110292780 | E12: =SUMIFS(Registro_OT!$P$2:$P$181, Registro_OT!$AM$2:$AM$181, 1) -> 106625870 | H12: =SUMIFS(Registro_OT!$T$2:$T$181, Registro_OT!$AM$2:$AM$181, 1) -> 93641900 | K12: =B12-E12 -> 3666910 | N12: =E12-H12 -> 12983970
B14: 3. MATRIZ DETALLADA DE TRIANGULACIÓN (ID PRESUPUESTO ➔ MECÁNICO ➔ ID OC ➔ ID FACTURA)
B15: ID OT | C15: Cliente | D15: Patente | E15: Mecánico Responsable | F15: ID Presupuesto | G15: Monto Presupuesto | H15: Estado Presupuesto | I15: ID OC Mandante | J15: Monto OC | K15: Estado OC | L15: ID Factura | M15: Monto Facturado | N15: Estado Cuadre 3-Way | O15: En Filtro
B16: =Registro_OT!A2 -> OT-0001 | C16: =Registro_OT!B2 -> CLI-015 | D16: =Registro_OT!C2 -> XSLT-12 | E16: =Registro_OT!H2 -> Luis Contreras | F16: =Registro_OT!J2 -> PRES-1001 | G16: =Registro_OT!L2 -> 243920 | H16: =Registro_OT!M2 -> Aprobado | I16: =Registro_OT!N2 -> OC-5001 | J16: =Registro_OT!P2 -> 243920 | K16: =Registro_OT!Q2 -> Recibida | L16: =Registro_OT!R2 -> FACT-3001 | M16: =Registro_OT!T2 -> 243920 | N16: =Registro_OT!W2 -> CUADRADO (3-WAY OK) | O16: =Registro_OT!AM2 -> 1
B17: =Registro_OT!A3 -> OT-0002 | C17: =Registro_OT!B3 -> CLI-015 | D17: =Registro_OT!C3 -> SKWX-95 | E17: =Registro_OT!H3 -> Marcelo Fuentes | F17: =Registro_OT!J3 -> PRES-1002 | G17: =Registro_OT!L3 -> 215570 | H17: =Registro_OT!M3 -> Aprobado | I17: =Registro_OT!N3 -> OC-5002 | J17: =Registro_OT!P3 -> 215570 | K17: =Registro_OT!Q3 -> Recibida | L17: =Registro_OT!R3 -> FACT-3002 | M17: =Registro_OT!T3 -> 215570 | N17: =Registro_OT!W3 -> CUADRADO (3-WAY OK) | O17: =Registro_OT!AM3 -> 1
B18: =Registro_OT!A4 -> OT-0003 | C18: =Registro_OT!B4 -> CLI-009 | D18: =Registro_OT!C4 -> RCYD-42 | E18: =Registro_OT!H4 -> Luis Contreras | F18: =Registro_OT!J4 -> PRES-1003 | G18: =Registro_OT!L4 -> 168410 | H18: =Registro_OT!M4 -> Aprobado | I18: =Registro_OT!N4 -> OC-5003 | J18: =Registro_OT!P4 -> 168410 | K18: =Registro_OT!Q4 -> Recibida | L18: =Registro_OT!R4 -> 0 | M18: =Registro_OT!T4 -> 0 | N18: =Registro_OT!W4 -> OC Recibida - Pendiente Factura | O18: =Registro_OT!AM4 -> 1
B19: =Registro_OT!A5 -> OT-0004 | C19: =Registro_OT!B5 -> CLI-009 | D19: =Registro_OT!C5 -> KZJV-65 | E19: =Registro_OT!H5 -> Daniela Mora | F19: =Registro_OT!J5 -> PRES-1004 | G19: =Registro_OT!L5 -> 971280 | H19: =Registro_OT!M5 -> Aprobado | I19: =Registro_OT!N5 -> OC-5004 | J19: =Registro_OT!P5 -> 971280 | K19: =Registro_OT!Q5 -> Recibida | L19: =Registro_OT!R5 -> FACT-3004 | M19: =Registro_OT!T5 -> 971280 | N19: =Registro_OT!W5 -> CUADRADO (3-WAY OK) | O19: =Registro_OT!AM5 -> 1
B20: =Registro_OT!A6 -> OT-0005 | C20: =Registro_OT!B6 -> CLI-013 | D20: =Registro_OT!C6 -> JVSV-33 | E20: =Registro_OT!H6 -> Luis Contreras | F20: =Registro_OT!J6 -> PRES-1005 | G20: =Registro_OT!L6 -> 562660 | H20: =Registro_OT!M6 -> Aprobado | I20: =Registro_OT!N6 -> OC-5005 | J20: =Registro_OT!P6 -> 562660 | K20: =Registro_OT!Q6 -> Recibida | L20: =Registro_OT!R6 -> FACT-3005 | M20: =Registro_OT!T6 -> 562660 | N20: =Registro_OT!W6 -> CUADRADO (3-WAY OK) | O20: =Registro_OT!AM6 -> 1
B21: =Registro_OT!A7 -> OT-0006 | C21: =Registro_OT!B7 -> CLI-017 | D21: =Registro_OT!C7 -> XYYK-56 | E21: =Registro_OT!H7 -> Sergio Valdés | F21: =Registro_OT!J7 -> PRES-1006 | G21: =Registro_OT!L7 -> 1311820 | H21: =Registro_OT!M7 -> Aprobado | I21: =Registro_OT!N7 -> OC-5006 | J21: =Registro_OT!P7 -> 1311820 | K21: =Registro_OT!Q7 -> Recibida | L21: =Registro_OT!R7 -> FACT-3006 | M21: =Registro_OT!T7 -> 1311820 | N21: =Registro_OT!W7 -> CUADRADO (3-WAY OK) | O21: =Registro_OT!AM7 -> 1
B22: =Registro_OT!A8 -> OT-0007 | C22: =Registro_OT!B8 -> CLI-013 | D22: =Registro_OT!C8 -> PZWS-75 | E22: =Registro_OT!H8 -> Luis Contreras | F22: =Registro_OT!J8 -> PRES-1007 | G22: =Registro_OT!L8 -> 338760 | H22: =Registro_OT!M8 -> Aprobado | I22: =Registro_OT!N8 -> OC-5007 | J22: =Registro_OT!P8 -> 338760 | K22: =Registro_OT!Q8 -> Recibida | L22: =Registro_OT!R8 -> FACT-3007 | M22: =Registro_OT!T8 -> 338760 | N22: =Registro_OT!W8 -> CUADRADO (3-WAY OK) | O22: =Registro_OT!AM8 -> 1
B23: =Registro_OT!A9 -> OT-0008 | C23: =Registro_OT!B9 -> CLI-001 | D23: =Registro_OT!C9 -> XPXS-10 | E23: =Registro_OT!H9 -> Daniela Mora | F23: =Registro_OT!J9 -> PRES-1008 | G23: =Registro_OT!L9 -> 916200 | H23: =Registro_OT!M9 -> Aprobado | I23: =Registro_OT!N9 -> OC-5008 | J23: =Registro_OT!P9 -> 916200 | K23: =Registro_OT!Q9 -> Recibida | L23: =Registro_OT!R9 -> FACT-3008 | M23: =Registro_OT!T9 -> 916200 | N23: =Registro_OT!W9 -> CUADRADO (3-WAY OK) | O23: =Registro_OT!AM9 -> 1
B24: =Registro_OT!A10 -> OT-0009 | C24: =Registro_OT!B10 -> CLI-018 | D24: =Registro_OT!C10 -> HYVX-61 | E24: =Registro_OT!H10 -> Marcelo Fuentes | F24: =Registro_OT!J10 -> PRES-1009 | G24: =Registro_OT!L10 -> 292060 | H24: =Registro_OT!M10 -> Aprobado | I24: =Registro_OT!N10 -> OC-5009 | J24: =Registro_OT!P10 -> 292060 | K24: =Registro_OT!Q10 -> Recibida | L24: =Registro_OT!R10 -> FACT-3009 | M24: =Registro_OT!T10 -> 292060 | N24: =Registro_OT!W10 -> CUADRADO (3-WAY OK) | O24: =Registro_OT!AM10 -> 1
B25: =Registro_OT!A11 -> OT-0010 | C25: =Registro_OT!B11 -> CLI-013 | D25: =Registro_OT!C11 -> KPHK-22 | E25: =Registro_OT!H11 -> Marcelo Fuentes | F25: =Registro_OT!J11 -> PRES-1010 | G25: =Registro_OT!L11 -> 418890 | H25: =Registro_OT!M11 -> Aprobado | I25: =Registro_OT!N11 -> OC-5010 | J25: =Registro_OT!P11 -> 418890 | K25: =Registro_OT!Q11 -> Recibida | L25: =Registro_OT!R11 -> FACT-3010 | M25: =Registro_OT!T11 -> 418890 | N25: =Registro_OT!W11 -> CUADRADO (3-WAY OK) | O25: =Registro_OT!AM11 -> 1
B26: =Registro_OT!A12 -> OT-0011 | C26: =Registro_OT!B12 -> CLI-003 | D26: =Registro_OT!C12 -> RFVZ-29 | E26: =Registro_OT!H12 -> Cristian Araya | F26: =Registro_OT!J12 -> PRES-1011 | G26: =Registro_OT!L12 -> 425890 | H26: =Registro_OT!M12 -> Aprobado | I26: =Registro_OT!N12 -> OC-5011 | J26: =Registro_OT!P12 -> 425890 | K26: =Registro_OT!Q12 -> Recibida | L26: =Registro_OT!R12 -> FACT-3011 | M26: =Registro_OT!T12 -> 425890 | N26: =Registro_OT!W12 -> CUADRADO (3-WAY OK) | O26: =Registro_OT!AM12 -> 1
B27: =Registro_OT!A13 -> OT-0012 | C27: =Registro_OT!B13 -> CLI-015 | D27: =Registro_OT!C13 -> FGXK-37 | E27: =Registro_OT!H13 -> Marcelo Fuentes | F27: =Registro_OT!J13 -> PRES-1012 | G27: =Registro_OT!L13 -> 1042280 | H27: =Registro_OT!M13 -> Aprobado | I27: =Registro_OT!N13 -> OC-5012 | J27: =Registro_OT!P13 -> 1042280 | K27: =Registro_OT!Q13 -> Recibida | L27: =Registro_OT!R13 -> FACT-3012 | M27: =Registro_OT!T13 -> 1042280 | N27: =Registro_OT!W13 -> CUADRADO (3-WAY OK) | O27: =Registro_OT!AM13 -> 1
... B195: =Registro_OT!A181 -> OT-0180 | C195: =Registro_OT!B181 -> CLI-012 | D195: =Registro_OT!C181 -> HSLY-32 | E195: =Registro_OT!H181 -> Luis Contreras | F195: =Registro_OT!J181 -> PRES-1180 | G195: =Registro_OT!L181 -> 1053870 | H195: =Registro_OT!M181 -> Pendiente | I195: =Registro_OT!N181 -> 0 | J195: =Registro_OT!P181 -> 0 | K195: =Registro_OT!Q181 -> Sin OC | L195: =Registro_OT!R181 -> 0 | M195: =Registro_OT!T181 -> 0 | N195: =Registro_OT!W181 -> Presupuesto No Aprobado | O195: =Registro_OT!AM181 -> 1

Sheet Dashboard
B1: DASHBOARD EJECUTIVO · TALLER DE MANTENCIÓN Y REPARACIÓN DE BUSES
B2: Prototipo de control operativo y financiero · datos sintéticos · montos en pesos chilenos (CLP)
B4: Fecha de corte | D4: Mes de ingreso | F4: Tipo de servicio | H4: Estado de OT | J4: Los filtros (celdas amarillas) afectan KPIs, Top 5 y gráficos. Las alertas muestran siempre la vista global. | O4: Datos de apoyo para gráficos (no editar)
B5: 46316 | D5: Todos | F5: Todos | H5: Todos | O5: Criterio tipo | P5: =IF(F5="Todos","*",F5) -> *
O6: Criterio estado | P6: =IF(H5="Todos","*",H5) -> *
B7: OPERACIÓN
B8: TOTAL OT DEL PERÍODO | D8: OT ABIERTAS | F8: OT ATRASADAS ACTIVAS | H8: % CUMPLIMIENTO DE PLAZOS | J8: DÍAS PROMEDIO EN TALLER | O8: Mes | P8: N° OT | Q8: Importe cobrable | R8: Costos directos
B9: =COUNTIFS(T_OrdenesTrabajo[En_Filtro],1) -> 180 | D9: =COUNTIFS(T_OrdenesTrabajo[En_Filtro],1,T_OrdenesTrabajo[Estado_OT],"En Curso")+COUNTIFS(T_OrdenesTrabajo[En_Filtro],1,T_OrdenesTrabajo[Estado_OT],"Reprogramada") -> 16 | F9: =SUMIFS(T_OrdenesTrabajo[Atrasada_Activa],T_OrdenesTrabajo[En_Filtro],1) -> 13 | H9: =IFERROR(SUMIFS(T_OrdenesTrabajo[Cumple_Plazo],T_OrdenesTrabajo[En_Filtro],1)/(COUNTIFS(T_OrdenesTrabajo[En_Filtro],1,T_OrdenesTrabajo[Cumple_Plazo],0)+COUNTIFS(T_OrdenesTrabajo[En_Filtro],1,T_OrdenesTrabajo[Cumple_Plazo],1)),0) -> 0.64634146 | J9: =IFERROR(AVERAGEIFS(T_OrdenesTrabajo[Dias_en_Taller],T_OrdenesTrabajo[En_Filtro],1,T_OrdenesTrabajo[Dias_en_Taller],">=0"),0) -> 7.3231707 | O9: 2026-05 | P9: =COUNTIFS(T_OrdenesTrabajo[Mes_Ingreso],O9,T_OrdenesTrabajo[Tipo_Servicio],$P$5,T_OrdenesTrabajo[Estado_OT],$P$6) -> 26 | Q9: =SUMIFS(T_OrdenesTrabajo[Monto_Total_Cobrable],T_OrdenesTrabajo[Mes_Ingreso],O9,T_OrdenesTrabajo[Tipo_Servicio],$P$5,T_OrdenesTrabajo[Estado_OT],$P$6) -> 15213860 | R9: =SUMIFS(T_OrdenesTrabajo[Costo_Materiales],T_OrdenesTrabajo[Mes_Ingreso],O9,T_OrdenesTrabajo[Tipo_Servicio],$P$5,T_OrdenesTrabajo[Estado_OT],$P$6)+SUMIFS(T_OrdenesTrabajo[Costo_Mano_Obra],T_OrdenesTrabajo[Mes_Ingreso],O9,T_OrdenesTrabajo[Tipo_Servicio],$P$5,T_OrdenesTrabajo[Estado_OT],$P$6) -> 9953510
O10: 2026-06 | P10: =COUNTIFS(T_OrdenesTrabajo[Mes_Ingreso],O10,T_OrdenesTrabajo[Tipo_Servicio],$P$5,T_OrdenesTrabajo[Estado_OT],$P$6) -> 23 | Q10: =SUMIFS(T_OrdenesTrabajo[Monto_Total_Cobrable],T_OrdenesTrabajo[Mes_Ingreso],O10,T_OrdenesTrabajo[Tipo_Servicio],$P$5,T_OrdenesTrabajo[Estado_OT],$P$6) -> 13115210 | R10: =SUMIFS(T_OrdenesTrabajo[Costo_Materiales],T_OrdenesTrabajo[Mes_Ingreso],O10,T_OrdenesTrabajo[Tipo_Servicio],$P$5,T_OrdenesTrabajo[Estado_OT],$P$6)+SUMIFS(T_OrdenesTrabajo[Costo_Mano_Obra],T_OrdenesTrabajo[Mes_Ingreso],O10,T_OrdenesTrabajo[Tipo_Servicio],$P$5,T_OrdenesTrabajo[Estado_OT],$P$6) -> 9010480
B11: ECONOMÍA | O11: 2026-07 | P11: =COUNTIFS(T_OrdenesTrabajo[Mes_Ingreso],O11,T_OrdenesTrabajo[Tipo_Servicio],$P$5,T_OrdenesTrabajo[Estado_OT],$P$6) -> 37 | Q11: =SUMIFS(T_OrdenesTrabajo[Monto_Total_Cobrable],T_OrdenesTrabajo[Mes_Ingreso],O11,T_OrdenesTrabajo[Tipo_Servicio],$P$5,T_OrdenesTrabajo[Estado_OT],$P$6) -> 21340780 | R11: =SUMIFS(T_OrdenesTrabajo[Costo_Materiales],T_OrdenesTrabajo[Mes_Ingreso],O11,T_OrdenesTrabajo[Tipo_Servicio],$P$5,T_OrdenesTrabajo[Estado_OT],$P$6)+SUMIFS(T_OrdenesTrabajo[Costo_Mano_Obra],T_OrdenesTrabajo[Mes_Ingreso],O11,T_OrdenesTrabajo[Tipo_Servicio],$P$5,T_OrdenesTrabajo[Estado_OT],$P$6) -> 15380320
B12: IMPORTE TOTAL COBRABLE | D12: COSTO DIRECTO MATERIALES | F12: COSTO DIRECTO MANO DE OBRA | H12: MARGEN DE CONTRIBUCIÓN ($) | J12: MARGEN DE CONTRIBUCIÓN (%) | O12: 2026-08 | P12: =COUNTIFS(T_OrdenesTrabajo[Mes_Ingreso],O12,T_OrdenesTrabajo[Tipo_Servicio],$P$5,T_OrdenesTrabajo[Estado_OT],$P$6) -> 40 | Q12: =SUMIFS(T_OrdenesTrabajo[Monto_Total_Cobrable],T_OrdenesTrabajo[Mes_Ingreso],O12,T_OrdenesTrabajo[Tipo_Servicio],$P$5,T_OrdenesTrabajo[Estado_OT],$P$6) -> 21826420 | R12: =SUMIFS(T_OrdenesTrabajo[Costo_Materiales],T_OrdenesTrabajo[Mes_Ingreso],O12,T_OrdenesTrabajo[Tipo_Servicio],$P$5,T_OrdenesTrabajo[Estado_OT],$P$6)+SUMIFS(T_OrdenesTrabajo[Costo_Mano_Obra],T_OrdenesTrabajo[Mes_Ingreso],O12,T_OrdenesTrabajo[Tipo_Servicio],$P$5,T_OrdenesTrabajo[Estado_OT],$P$6) -> 14343140
B13: =SUMIFS(T_OrdenesTrabajo[Monto_Total_Cobrable],T_OrdenesTrabajo[En_Filtro],1) -> 110292780 | D13: =SUMIFS(T_OrdenesTrabajo[Costo_Materiales],T_OrdenesTrabajo[En_Filtro],1) -> 46808500 | F13: =SUMIFS(T_OrdenesTrabajo[Costo_Mano_Obra],T_OrdenesTrabajo[En_Filtro],1) -> 28981900 | H13: =B13-D13-F13 -> 34502380 | J13: =IFERROR(H13/B13,0) -> 0.31282537 | O13: 2026-09 | P13: =COUNTIFS(T_OrdenesTrabajo[Mes_Ingreso],O13,T_OrdenesTrabajo[Tipo_Servicio],$P$5,T_OrdenesTrabajo[Estado_OT],$P$6) -> 34 | Q13: =SUMIFS(T_OrdenesTrabajo[Monto_Total_Cobrable],T_OrdenesTrabajo[Mes_Ingreso],O13,T_OrdenesTrabajo[Tipo_Servicio],$P$5,T_OrdenesTrabajo[Estado_OT],$P$6) -> 25884000 | R13: =SUMIFS(T_OrdenesTrabajo[Costo_Materiales],T_OrdenesTrabajo[Mes_Ingreso],O13,T_OrdenesTrabajo[Tipo_Servicio],$P$5,T_OrdenesTrabajo[Estado_OT],$P$6)+SUMIFS(T_OrdenesTrabajo[Costo_Mano_Obra],T_OrdenesTrabajo[Mes_Ingreso],O13,T_OrdenesTrabajo[Tipo_Servicio],$P$5,T_OrdenesTrabajo[Estado_OT],$P$6) -> 18609970
O14: 2026-10 | P14: =COUNTIFS(T_OrdenesTrabajo[Mes_Ingreso],O14,T_OrdenesTrabajo[Tipo_Servicio],$P$5,T_OrdenesTrabajo[Estado_OT],$P$6) -> 20 | Q14: =SUMIFS(T_OrdenesTrabajo[Monto_Total_Cobrable],T_OrdenesTrabajo[Mes_Ingreso],O14,T_OrdenesTrabajo[Tipo_Servicio],$P$5,T_OrdenesTrabajo[Estado_OT],$P$6) -> 12912510 | R14: =SUMIFS(T_OrdenesTrabajo[Costo_Materiales],T_OrdenesTrabajo[Mes_Ingreso],O14,T_OrdenesTrabajo[Tipo_Servicio],$P$5,T_OrdenesTrabajo[Estado_OT],$P$6)+SUMIFS(T_OrdenesTrabajo[Costo_Mano_Obra],T_OrdenesTrabajo[Mes_Ingreso],O14,T_OrdenesTrabajo[Tipo_Servicio],$P$5,T_OrdenesTrabajo[Estado_OT],$P$6) -> 8492980
B15: MATERIALES · TOP 5 REPUESTOS
B16: # | C16: Por cantidad usada | E16: Cantidad | G16: # | H16: Por costo de consumo | J16: Costo ($)
B17: 1 | C17: =IFERROR(INDEX(T_Repuestos[Descripcion_Repuesto],MATCH(1,T_Repuestos[Rank_Cantidad],0)),"") -> Aceite de caja 80W90 | E17: =IFERROR(INDEX(T_Repuestos[Cantidad_Usada],MATCH(1,T_Repuestos[Rank_Cantidad],0)),0) -> 415 | G17: 1 | H17: =IFERROR(INDEX(T_Repuestos[Descripcion_Repuesto],MATCH(1,T_Repuestos[Rank_Costo],0)),"") -> Parabrisas panorámico | J17: =IFERROR(INDEX(T_Repuestos[Costo_Consumo],MATCH(1,T_Repuestos[Rank_Costo],0)),0) -> 6765540
B18: 2 | C18: =IFERROR(INDEX(T_Repuestos[Descripcion_Repuesto],MATCH(2,T_Repuestos[Rank_Cantidad],0)),"") -> Refrigerante concentrado | E18: =IFERROR(INDEX(T_Repuestos[Cantidad_Usada],MATCH(2,T_Repuestos[Rank_Cantidad],0)),0) -> 352 | G18: 2 | H18: =IFERROR(INDEX(T_Repuestos[Descripcion_Repuesto],MATCH(2,T_Repuestos[Rank_Costo],0)),"") -> Balón neumático (fuelle) | J18: =IFERROR(INDEX(T_Repuestos[Costo_Consumo],MATCH(2,T_Repuestos[Rank_Costo],0)),0) -> 5065910
B19: 3 | C19: =IFERROR(INDEX(T_Repuestos[Descripcion_Repuesto],MATCH(3,T_Repuestos[Rank_Cantidad],0)),"") -> Aceite motor 15W40 | E19: =IFERROR(INDEX(T_Repuestos[Cantidad_Usada],MATCH(3,T_Repuestos[Rank_Cantidad],0)),0) -> 276 | G19: 3 | H19: =IFERROR(INDEX(T_Repuestos[Descripcion_Repuesto],MATCH(3,T_Repuestos[Rank_Costo],0)),"") -> Panel lateral de fibra | J19: =IFERROR(INDEX(T_Repuestos[Costo_Consumo],MATCH(3,T_Repuestos[Rank_Costo],0)),0) -> 4140070
B20: 4 | C20: =IFERROR(INDEX(T_Repuestos[Descripcion_Repuesto],MATCH(4,T_Repuestos[Rank_Cantidad],0)),"") -> Pintura esmalte para bus | E20: =IFERROR(INDEX(T_Repuestos[Cantidad_Usada],MATCH(4,T_Repuestos[Rank_Cantidad],0)),0) -> 93 | G20: 4 | H20: =IFERROR(INDEX(T_Repuestos[Descripcion_Repuesto],MATCH(4,T_Repuestos[Rank_Costo],0)),"") -> Luneta trasera | J20: =IFERROR(INDEX(T_Repuestos[Costo_Consumo],MATCH(4,T_Repuestos[Rank_Costo],0)),0) -> 2767420
B21: 5 | C21: =IFERROR(INDEX(T_Repuestos[Descripcion_Repuesto],MATCH(5,T_Repuestos[Rank_Cantidad],0)),"") -> Filtro de combustible | E21: =IFERROR(INDEX(T_Repuestos[Cantidad_Usada],MATCH(5,T_Repuestos[Rank_Cantidad],0)),0) -> 62 | G21: 5 | H21: =IFERROR(INDEX(T_Repuestos[Descripcion_Repuesto],MATCH(5,T_Repuestos[Rank_Costo],0)),"") -> Aceite de caja 80W90 | J21: =IFERROR(INDEX(T_Repuestos[Costo_Consumo],MATCH(5,T_Repuestos[Rank_Costo],0)),0) -> 2648980
B23: ALERTAS Y EXCEPCIONES · VISTA GLOBAL
B24: ="OT atrasadas aún abiertas ("&SUM(T_OrdenesTrabajo[Atrasada_Activa])&")" -> OT atrasadas aún abiertas (13) | F24: ="Terminadas pendientes de facturar ("&SUM(T_OrdenesTrabajo[Pend_Facturacion])&")" -> Terminadas pendientes de facturar (10) | J24: ="OT con costos/precios faltantes ("&SUM(T_OrdenesTrabajo[Dato_Incompleto])&")" -> OT con costos/precios faltantes (12)
B25: ID_OT | C25: Patente | D25: Días de atraso | F25: ID_OT | G25: Patente | H25: Monto por facturar | J25: ID_OT | K25: Patente | L25: Líneas incompletas
B26: =IFERROR(INDEX(T_OrdenesTrabajo[ID_OT],MATCH(1,T_OrdenesTrabajo[Seq_Atrasada],0)),"") -> OT-0015 | C26: =IF(B26="","",INDEX(T_OrdenesTrabajo[Patente_Bus],MATCH(B26,T_OrdenesTrabajo[ID_OT],0))) -> DCTS-30 | D26: =IF(B26="","",$B$5-INDEX(T_OrdenesTrabajo[Fecha_Compromiso],MATCH(B26,T_OrdenesTrabajo[ID_OT],0))) -> 153 | F26: =IFERROR(INDEX(T_OrdenesTrabajo[ID_OT],MATCH(1,T_OrdenesTrabajo[Seq_Pend_Fact],0)),"") -> OT-0003 | G26: =IF(F26="","",INDEX(T_OrdenesTrabajo[Patente_Bus],MATCH(F26,T_OrdenesTrabajo[ID_OT],0))) -> RCYD-42 | H26: =IF(F26="","",INDEX(T_OrdenesTrabajo[Monto_Total_Cobrable],MATCH(F26,T_OrdenesTrabajo[ID_OT],0))) -> 168410 | J26: =IFERROR(INDEX(T_OrdenesTrabajo[ID_OT],MATCH(1,T_OrdenesTrabajo[Seq_Incompleta],0)),"") -> OT-0028 | K26: =IF(J26="","",INDEX(T_OrdenesTrabajo[Patente_Bus],MATCH(J26,T_OrdenesTrabajo[ID_OT],0))) -> KJYZ-42 | L26: =IF(J26="","",SUMIFS(T_DetalleOT[Alerta_Dato],T_DetalleOT[ID_OT],J26)) -> 1
B27: =IFERROR(INDEX(T_OrdenesTrabajo[ID_OT],MATCH(2,T_OrdenesTrabajo[Seq_Atrasada],0)),"") -> OT-0054 | C27: =IF(B27="","",INDEX(T_OrdenesTrabajo[Patente_Bus],MATCH(B27,T_OrdenesTrabajo[ID_OT],0))) -> BVXG-76 | D27: =IF(B27="","",$B$5-INDEX(T_OrdenesTrabajo[Fecha_Compromiso],MATCH(B27,T_OrdenesTrabajo[ID_OT],0))) -> 104 | F27: =IFERROR(INDEX(T_OrdenesTrabajo[ID_OT],MATCH(2,T_OrdenesTrabajo[Seq_Pend_Fact],0)),"") -> OT-0036 | G27: =IF(F27="","",INDEX(T_OrdenesTrabajo[Patente_Bus],MATCH(F27,T_OrdenesTrabajo[ID_OT],0))) -> FZSK-81 | H27: =IF(F27="","",INDEX(T_OrdenesTrabajo[Monto_Total_Cobrable],MATCH(F27,T_OrdenesTrabajo[ID_OT],0))) -> 390620 | J27: =IFERROR(INDEX(T_OrdenesTrabajo[ID_OT],MATCH(2,T_OrdenesTrabajo[Seq_Incompleta],0)),"") -> OT-0063 | K27: =IF(J27="","",INDEX(T_OrdenesTrabajo[Patente_Bus],MATCH(J27,T_OrdenesTrabajo[ID_OT],0))) -> WTWL-98 | L27: =IF(J27="","",SUMIFS(T_DetalleOT[Alerta_Dato],T_DetalleOT[ID_OT],J27)) -> 1
B28: =IFERROR(INDEX(T_OrdenesTrabajo[ID_OT],MATCH(3,T_OrdenesTrabajo[Seq_Atrasada],0)),"") -> OT-0064 | C28: =IF(B28="","",INDEX(T_OrdenesTrabajo[Patente_Bus],MATCH(B28,T_OrdenesTrabajo[ID_OT],0))) -> DCZJ-61 | D28: =IF(B28="","",$B$5-INDEX(T_OrdenesTrabajo[Fecha_Compromiso],MATCH(B28,T_OrdenesTrabajo[ID_OT],0))) -> 86 | F28: =IFERROR(INDEX(T_OrdenesTrabajo[ID_OT],MATCH(3,T_OrdenesTrabajo[Seq_Pend_Fact],0)),"") -> OT-0045 | G28: =IF(F28="","",INDEX(T_OrdenesTrabajo[Patente_Bus],MATCH(F28,T_OrdenesTrabajo[ID_OT],0))) -> JXLB-86 | H28: =IF(F28="","",INDEX(T_OrdenesTrabajo[Monto_Total_Cobrable],MATCH(F28,T_OrdenesTrabajo[ID_OT],0))) -> 908960 | J28: =IFERROR(INDEX(T_OrdenesTrabajo[ID_OT],MATCH(3,T_OrdenesTrabajo[Seq_Incompleta],0)),"") -> OT-0070 | K28: =IF(J28="","",INDEX(T_OrdenesTrabajo[Patente_Bus],MATCH(J28,T_OrdenesTrabajo[ID_OT],0))) -> LPYZ-21 | L28: =IF(J28="","",SUMIFS(T_DetalleOT[Alerta_Dato],T_DetalleOT[ID_OT],J28)) -> 1
B29: =IFERROR(INDEX(T_OrdenesTrabajo[ID_OT],MATCH(4,T_OrdenesTrabajo[Seq_Atrasada],0)),"") -> OT-0098 | C29: =IF(B29="","",INDEX(T_OrdenesTrabajo[Patente_Bus],MATCH(B29,T_OrdenesTrabajo[ID_OT],0))) -> GWVV-51 | D29: =IF(B29="","",$B$5-INDEX(T_OrdenesTrabajo[Fecha_Compromiso],MATCH(B29,T_OrdenesTrabajo[ID_OT],0))) -> 70 | F29: =IFERROR(INDEX(T_OrdenesTrabajo[ID_OT],MATCH(4,T_OrdenesTrabajo[Seq_Pend_Fact],0)),"") -> OT-0087 | G29: =IF(F29="","",INDEX(T_OrdenesTrabajo[Patente_Bus],MATCH(F29,T_OrdenesTrabajo[ID_OT],0))) -> BHDW-82 | H29: =IF(F29="","",INDEX(T_OrdenesTrabajo[Monto_Total_Cobrable],MATCH(F29,T_OrdenesTrabajo[ID_OT],0))) -> 549400 | J29: =IFERROR(INDEX(T_OrdenesTrabajo[ID_OT],MATCH(4,T_OrdenesTrabajo[Seq_Incompleta],0)),"") -> OT-0072 | K29: =IF(J29="","",INDEX(T_OrdenesTrabajo[Patente_Bus],MATCH(J29,T_OrdenesTrabajo[ID_OT],0))) -> YJHP-79 | L29: =IF(J29="","",SUMIFS(T_DetalleOT[Alerta_Dato],T_DetalleOT[ID_OT],J29)) -> 1
B30: =IFERROR(INDEX(T_OrdenesTrabajo[ID_OT],MATCH(5,T_OrdenesTrabajo[Seq_Atrasada],0)),"") -> OT-0109 | C30: =IF(B30="","",INDEX(T_OrdenesTrabajo[Patente_Bus],MATCH(B30,T_OrdenesTrabajo[ID_OT],0))) -> KTJH-57 | D30: =IF(B30="","",$B$5-INDEX(T_OrdenesTrabajo[Fecha_Compromiso],MATCH(B30,T_OrdenesTrabajo[ID_OT],0))) -> 67 | F30: =IFERROR(INDEX(T_OrdenesTrabajo[ID_OT],MATCH(5,T_OrdenesTrabajo[Seq_Pend_Fact],0)),"") -> OT-0107 | G30: =IF(F30="","",INDEX(T_OrdenesTrabajo[Patente_Bus],MATCH(F30,T_OrdenesTrabajo[ID_OT],0))) -> HTCP-28 | H30: =IF(F30="","",INDEX(T_OrdenesTrabajo[Monto_Total_Cobrable],MATCH(F30,T_OrdenesTrabajo[ID_OT],0))) -> 142160 | J30: =IFERROR(INDEX(T_OrdenesTrabajo[ID_OT],MATCH(5,T_OrdenesTrabajo[Seq_Incompleta],0)),"") -> OT-0101 | K30: =IF(J30="","",INDEX(T_OrdenesTrabajo[Patente_Bus],MATCH(J30,T_OrdenesTrabajo[ID_OT],0))) -> KVHY-74 | L30: =IF(J30="","",SUMIFS(T_DetalleOT[Alerta_Dato],T_DetalleOT[ID_OT],J30)) -> 1
B31: =IFERROR(INDEX(T_OrdenesTrabajo[ID_OT],MATCH(6,T_OrdenesTrabajo[Seq_Atrasada],0)),"") -> OT-0115 | C31: =IF(B31="","",INDEX(T_OrdenesTrabajo[Patente_Bus],MATCH(B31,T_OrdenesTrabajo[ID_OT],0))) -> CFLD-34 | D31: =IF(B31="","",$B$5-INDEX(T_OrdenesTrabajo[Fecha_Compromiso],MATCH(B31,T_OrdenesTrabajo[ID_OT],0))) -> 61 | F31: =IFERROR(INDEX(T_OrdenesTrabajo[ID_OT],MATCH(6,T_OrdenesTrabajo[Seq_Pend_Fact],0)),"") -> OT-0159 | G31: =IF(F31="","",INDEX(T_OrdenesTrabajo[Patente_Bus],MATCH(F31,T_OrdenesTrabajo[ID_OT],0))) -> HHSL-48 | H31: =IF(F31="","",INDEX(T_OrdenesTrabajo[Monto_Total_Cobrable],MATCH(F31,T_OrdenesTrabajo[ID_OT],0))) -> 1106980 | J31: =IFERROR(INDEX(T_OrdenesTrabajo[ID_OT],MATCH(6,T_OrdenesTrabajo[Seq_Incompleta],0)),"") -> OT-0115 | K31: =IF(J31="","",INDEX(T_OrdenesTrabajo[Patente_Bus],MATCH(J31,T_OrdenesTrabajo[ID_OT],0))) -> CFLD-34 | L31: =IF(J31="","",SUMIFS(T_DetalleOT[Alerta_Dato],T_DetalleOT[ID_OT],J31)) -> 1
B32: =IFERROR(INDEX(T_OrdenesTrabajo[ID_OT],MATCH(7,T_OrdenesTrabajo[Seq_Atrasada],0)),"") -> OT-0116 | C32: =IF(B32="","",INDEX(T_OrdenesTrabajo[Patente_Bus],MATCH(B32,T_OrdenesTrabajo[ID_OT],0))) -> LJPY-44 | D32: =IF(B32="","",$B$5-INDEX(T_OrdenesTrabajo[Fecha_Compromiso],MATCH(B32,T_OrdenesTrabajo[ID_OT],0))) -> 55 | F32: =IFERROR(INDEX(T_OrdenesTrabajo[ID_OT],MATCH(7,T_OrdenesTrabajo[Seq_Pend_Fact],0)),"") -> OT-0165 | G32: =IF(F32="","",INDEX(T_OrdenesTrabajo[Patente_Bus],MATCH(F32,T_OrdenesTrabajo[ID_OT],0))) -> SKSX-53 | H32: =IF(F32="","",INDEX(T_OrdenesTrabajo[Monto_Total_Cobrable],MATCH(F32,T_OrdenesTrabajo[ID_OT],0))) -> 133430 | J32: =IFERROR(INDEX(T_OrdenesTrabajo[ID_OT],MATCH(7,T_OrdenesTrabajo[Seq_Incompleta],0)),"") -> OT-0128 | K32: =IF(J32="","",INDEX(T_OrdenesTrabajo[Patente_Bus],MATCH(J32,T_OrdenesTrabajo[ID_OT],0))) -> HWXT-20 | L32: =IF(J32="","",SUMIFS(T_DetalleOT[Alerta_Dato],T_DetalleOT[ID_OT],J32)) -> 2
B33: =IFERROR(INDEX(T_OrdenesTrabajo[ID_OT],MATCH(8,T_OrdenesTrabajo[Seq_Atrasada],0)),"") -> OT-0132 | C33: =IF(B33="","",INDEX(T_OrdenesTrabajo[Patente_Bus],MATCH(B33,T_OrdenesTrabajo[ID_OT],0))) -> BBYC-90 | D33: =IF(B33="","",$B$5-INDEX(T_OrdenesTrabajo[Fecha_Compromiso],MATCH(B33,T_OrdenesTrabajo[ID_OT],0))) -> 39 | F33: =IFERROR(INDEX(T_OrdenesTrabajo[ID_OT],MATCH(8,T_OrdenesTrabajo[Seq_Pend_Fact],0)),"") -> OT-0167 | G33: =IF(F33="","",INDEX(T_OrdenesTrabajo[Patente_Bus],MATCH(F33,T_OrdenesTrabajo[ID_OT],0))) -> JBSB-61 | H33: =IF(F33="","",INDEX(T_OrdenesTrabajo[Monto_Total_Cobrable],MATCH(F33,T_OrdenesTrabajo[ID_OT],0))) -> 735130 | J33: =IFERROR(INDEX(T_OrdenesTrabajo[ID_OT],MATCH(8,T_OrdenesTrabajo[Seq_Incompleta],0)),"") -> OT-0130 | K33: =IF(J33="","",INDEX(T_OrdenesTrabajo[Patente_Bus],MATCH(J33,T_OrdenesTrabajo[ID_OT],0))) -> YFDR-92 | L33: =IF(J33="","",SUMIFS(T_DetalleOT[Alerta_Dato],T_DetalleOT[ID_OT],J33)) -> 1
B34: =IFERROR(INDEX(T_OrdenesTrabajo[ID_OT],MATCH(9,T_OrdenesTrabajo[Seq_Atrasada],0)),"") -> OT-0137 | C34: =IF(B34="","",INDEX(T_OrdenesTrabajo[Patente_Bus],MATCH(B34,T_OrdenesTrabajo[ID_OT],0))) -> HZTY-87 | D34: =IF(B34="","",$B$5-INDEX(T_OrdenesTrabajo[Fecha_Compromiso],MATCH(B34,T_OrdenesTrabajo[ID_OT],0))) -> 27 | F34: =IFERROR(INDEX(T_OrdenesTrabajo[ID_OT],MATCH(9,T_OrdenesTrabajo[Seq_Pend_Fact],0)),"") -> OT-0171 | G34: =IF(F34="","",INDEX(T_OrdenesTrabajo[Patente_Bus],MATCH(F34,T_OrdenesTrabajo[ID_OT],0))) -> SPJG-50 | H34: =IF(F34="","",INDEX(T_OrdenesTrabajo[Monto_Total_Cobrable],MATCH(F34,T_OrdenesTrabajo[ID_OT],0))) -> 188640 | J34: =IFERROR(INDEX(T_OrdenesTrabajo[ID_OT],MATCH(9,T_OrdenesTrabajo[Seq_Incompleta],0)),"") -> OT-0134 | K34: =IF(J34="","",INDEX(T_OrdenesTrabajo[Patente_Bus],MATCH(J34,T_OrdenesTrabajo[ID_OT],0))) -> ZXHS-43 | L34: =IF(J34="","",SUMIFS(T_DetalleOT[Alerta_Dato],T_DetalleOT[ID_OT],J34)) -> 1
B35: =IFERROR(INDEX(T_OrdenesTrabajo[ID_OT],MATCH(10,T_OrdenesTrabajo[Seq_Atrasada],0)),"") -> OT-0149 | C35: =IF(B35="","",INDEX(T_OrdenesTrabajo[Patente_Bus],MATCH(B35,T_OrdenesTrabajo[ID_OT],0))) -> WJKW-90 | D35: =IF(B35="","",$B$5-INDEX(T_OrdenesTrabajo[Fecha_Compromiso],MATCH(B35,T_OrdenesTrabajo[ID_OT],0))) -> 15 | F35: =IFERROR(INDEX(T_OrdenesTrabajo[ID_OT],MATCH(10,T_OrdenesTrabajo[Seq_Pend_Fact],0)),"") -> OT-0175 | G35: =IF(F35="","",INDEX(T_OrdenesTrabajo[Patente_Bus],MATCH(F35,T_OrdenesTrabajo[ID_OT],0))) -> LRWP-21 | H35: =IF(F35="","",INDEX(T_OrdenesTrabajo[Monto_Total_Cobrable],MATCH(F35,T_OrdenesTrabajo[ID_OT],0))) -> 789780 | J35: =IFERROR(INDEX(T_OrdenesTrabajo[ID_OT],MATCH(10,T_OrdenesTrabajo[Seq_Incompleta],0)),"") -> OT-0141 | K35: =IF(J35="","",INDEX(T_OrdenesTrabajo[Patente_Bus],MATCH(J35,T_OrdenesTrabajo[ID_OT],0))) -> RWBB-77 | L35: =IF(J35="","",SUMIFS(T_DetalleOT[Alerta_Dato],T_DetalleOT[ID_OT],J35)) -> 1
B36: =IFERROR(INDEX(T_OrdenesTrabajo[ID_OT],MATCH(11,T_OrdenesTrabajo[Seq_Atrasada],0)),"") -> OT-0169 | C36: =IF(B36="","",INDEX(T_OrdenesTrabajo[Patente_Bus],MATCH(B36,T_OrdenesTrabajo[ID_OT],0))) -> SFBJ-83 | D36: =IF(B36="","",$B$5-INDEX(T_OrdenesTrabajo[Fecha_Compromiso],MATCH(B36,T_OrdenesTrabajo[ID_OT],0))) -> 11 | F36: =IFERROR(INDEX(T_OrdenesTrabajo[ID_OT],MATCH(11,T_OrdenesTrabajo[Seq_Pend_Fact],0)),"") | G36: =IF(F36="","",INDEX(T_OrdenesTrabajo[Patente_Bus],MATCH(F36,T_OrdenesTrabajo[ID_OT],0))) | H36: =IF(F36="","",INDEX(T_OrdenesTrabajo[Monto_Total_Cobrable],MATCH(F36,T_OrdenesTrabajo[ID_OT],0))) | J36: =IFERROR(INDEX(T_OrdenesTrabajo[ID_OT],MATCH(11,T_OrdenesTrabajo[Seq_Incompleta],0)),"") -> OT-0145 | K36: =IF(J36="","",INDEX(T_OrdenesTrabajo[Patente_Bus],MATCH(J36,T_OrdenesTrabajo[ID_OT],0))) -> XBKZ-17 | L36: =IF(J36="","",SUMIFS(T_DetalleOT[Alerta_Dato],T_DetalleOT[ID_OT],J36)) -> 1
B37: =IFERROR(INDEX(T_OrdenesTrabajo[ID_OT],MATCH(12,T_OrdenesTrabajo[Seq_Atrasada],0)),"") -> OT-0176 | C37: =IF(B37="","",INDEX(T_OrdenesTrabajo[Patente_Bus],MATCH(B37,T_OrdenesTrabajo[ID_OT],0))) -> TCKP-77 | D37: =IF(B37="","",$B$5-INDEX(T_OrdenesTrabajo[Fecha_Compromiso],MATCH(B37,T_OrdenesTrabajo[ID_OT],0))) -> 2 | F37: =IFERROR(INDEX(T_OrdenesTrabajo[ID_OT],MATCH(12,T_OrdenesTrabajo[Seq_Pend_Fact],0)),"") | G37: =IF(F37="","",INDEX(T_OrdenesTrabajo[Patente_Bus],MATCH(F37,T_OrdenesTrabajo[ID_OT],0))) | H37: =IF(F37="","",INDEX(T_OrdenesTrabajo[Monto_Total_Cobrable],MATCH(F37,T_OrdenesTrabajo[ID_OT],0))) | J37: =IFERROR(INDEX(T_OrdenesTrabajo[ID_OT],MATCH(12,T_OrdenesTrabajo[Seq_Incompleta],0)),"") -> OT-0169 | K37: =IF(J37="","",INDEX(T_OrdenesTrabajo[Patente_Bus],MATCH(J37,T_OrdenesTrabajo[ID_OT],0))) -> SFBJ-83 | L37: =IF(J37="","",SUMIFS(T_DetalleOT[Alerta_Dato],T_DetalleOT[ID_OT],J37)) -> 1
B38: Cada lista muestra las primeras 12 OT (orden cronológico de ingreso). El listado completo se obtiene filtrando las columnas Atrasada_Activa, Pend_Facturacion o Dato_Incompleto en Registro_OT.
B40: GRÁFICOS

Sheet Dashboard_Mecanicos
B1: DASHBOARD DE RENDIMIENTO Y PRODUCTIVIDAD DE MECÁNICOS / VENDEDORES
B2: Análisis comparativo de carga de trabajo, facturación generada por Ordenes de Compra/Facturas y aportes de margen por técnico/vendedor
B4: 1. DESTACADOS DE PRODUCTIVIDAD Y FACTURACIÓN DEL TALLER
B5: MECÁNICO MÁS PRODUCTIVO | F5: MECÁNICO MAYOR FACTURACIÓN | J5: MAYOR MARGEN GENERADO
B6: =INDEX(Maestro_Tecnicos!$B$2:$B$9, MATCH(MAX(Dashboard_Mecanicos!$E$13:$E$20), Dashboard_Mecanicos!$E$13:$E$20, 0)) -> Marcelo Fuentes | F6: =INDEX(Maestro_Tecnicos!$B$2:$B$9, MATCH(MAX(Dashboard_Mecanicos!$I$13:$I$20), Dashboard_Mecanicos!$I$13:$I$20, 0)) -> Daniela Mora | J6: =INDEX(Maestro_Tecnicos!$B$2:$B$9, MATCH(MAX(Dashboard_Mecanicos!$J$13:$J$20), Dashboard_Mecanicos!$J$13:$J$20, 0)) -> Daniela Mora
B7: =MAX(Dashboard_Mecanicos!$E$13:$E$20) -> 43 | D7: OT | F7: =MAX(Dashboard_Mecanicos!$I$13:$I$20) -> 18254500 | J7: =MAX(Dashboard_Mecanicos!$J$13:$J$20) -> 8062860
F8: Facturado | J8: =MAX(Dashboard_Mecanicos!$J$13:$J$20)/$J$21 -> 0.24072371
B10: 2. MATRIZ COMPARATIVA DE MANTENCIONES Y FACTURACIÓN POR MECÁNICO / VENDEDOR
B11: 2. MATRIZ COMPARATIVA DE MANTENCIONES Y FACTURACIÓN POR MECÁNICO / VENDEDOR | C11: Nombre Mecánico / Vendedor | D11: Especialidad | E11: Total OTs | F11: Preventivos | G11: Correctivos | H11: Siniestros | I11: Facturación Real (OC/Factura) ($) | J11: Margen Generado ($) | K11: % Aporte Margen Taller
B12: ID Técnico | C12: Nombre Mecánico / Vendedor | D12: Especialidad | E12: Total OTs | F12: Preventivos | G12: Correctivos | H12: Siniestros | I12: Facturación Real (OC/Factura) ($) | J12: Margen Generado ($) | K12: % Aporte Margen Taller
B13: =Maestro_Tecnicos!A2 -> TEC-01 | C13: =Maestro_Tecnicos!B2 -> Marcelo Fuentes | D13: =Maestro_Tecnicos!C2 -> Mecánica General | E13: =COUNTIF(Registro_OT!$H$2:$H$181, C13) -> 43 | F13: =COUNTIFS(Registro_OT!$H$2:$H$181, C13, Registro_OT!$D$2:$D$181, "Preventivo") -> 26 | G13: =COUNTIFS(Registro_OT!$H$2:$H$181, C13, Registro_OT!$D$2:$D$181, "Correctivo/Falla") -> 0 | H13: =COUNTIFS(Registro_OT!$H$2:$H$181, C13, Registro_OT!$D$2:$D$181, "Siniestro/Carrocería") -> 2 | I13: =SUMIF(Registro_OT!$H$2:$H$181, C13, Registro_OT!$T$2:$T$181) -> 16388220 | J13: =SUMIF(Registro_OT!$H$2:$H$181, C13, Registro_OT!$AA$2:$AA$181) -> 4978050 | K13: =IF($J$21>0, J13/$J$21, 0) -> 0.14862402
B14: =Maestro_Tecnicos!A3 -> TEC-02 | C14: =Maestro_Tecnicos!B3 -> Cristian Araya | D14: =Maestro_Tecnicos!C3 -> Mecánica General | E14: =COUNTIF(Registro_OT!$H$2:$H$181, C14) -> 41 | F14: =COUNTIFS(Registro_OT!$H$2:$H$181, C14, Registro_OT!$D$2:$D$181, "Preventivo") -> 19 | G14: =COUNTIFS(Registro_OT!$H$2:$H$181, C14, Registro_OT!$D$2:$D$181, "Correctivo/Falla") -> 0 | H14: =COUNTIFS(Registro_OT!$H$2:$H$181, C14, Registro_OT!$D$2:$D$181, "Siniestro/Carrocería") -> 3 | I14: =SUMIF(Registro_OT!$H$2:$H$181, C14, Registro_OT!$T$2:$T$181) -> 14376150 | J14: =SUMIF(Registro_OT!$H$2:$H$181, C14, Registro_OT!$AA$2:$AA$181) -> 4911870 | K14: =IF($J$21>0, J14/$J$21, 0) -> 0.14664816
B15: =Maestro_Tecnicos!A4 -> TEC-03 | C15: =Maestro_Tecnicos!B4 -> Luis Contreras | D15: =Maestro_Tecnicos!C4 -> Mecánica General | E15: =COUNTIF(Registro_OT!$H$2:$H$181, C15) -> 37 | F15: =COUNTIFS(Registro_OT!$H$2:$H$181, C15, Registro_OT!$D$2:$D$181, "Preventivo") -> 20 | G15: =COUNTIFS(Registro_OT!$H$2:$H$181, C15, Registro_OT!$D$2:$D$181, "Correctivo/Falla") -> 0 | H15: =COUNTIFS(Registro_OT!$H$2:$H$181, C15, Registro_OT!$D$2:$D$181, "Siniestro/Carrocería") -> 0 | I15: =SUMIF(Registro_OT!$H$2:$H$181, C15, Registro_OT!$T$2:$T$181) -> 13057260 | J15: =SUMIF(Registro_OT!$H$2:$H$181, C15, Registro_OT!$AA$2:$AA$181) -> 4716150 | K15: =IF($J$21>0, J15/$J$21, 0) -> 0.14080476
B16: =Maestro_Tecnicos!A5 -> TEC-04 | C16: =Maestro_Tecnicos!B5 -> Patricio Rojas | D16: =Maestro_Tecnicos!C5 -> Carrocería/Siniestros | E16: =COUNTIF(Registro_OT!$H$2:$H$181, C16) -> 10 | F16: =COUNTIFS(Registro_OT!$H$2:$H$181, C16, Registro_OT!$D$2:$D$181, "Preventivo") -> 0 | G16: =COUNTIFS(Registro_OT!$H$2:$H$181, C16, Registro_OT!$D$2:$D$181, "Correctivo/Falla") -> 0 | H16: =COUNTIFS(Registro_OT!$H$2:$H$181, C16, Registro_OT!$D$2:$D$181, "Siniestro/Carrocería") -> 10 | I16: =SUMIF(Registro_OT!$H$2:$H$181, C16, Registro_OT!$T$2:$T$181) -> 10856270 | J16: =SUMIF(Registro_OT!$H$2:$H$181, C16, Registro_OT!$AA$2:$AA$181) -> 3786660 | K16: =IF($J$21>0, J16/$J$21, 0) -> 0.11305403
B17: =Maestro_Tecnicos!A6 -> TEC-05 | C17: =Maestro_Tecnicos!B6 -> Sergio Valdés | D17: =Maestro_Tecnicos!C6 -> Carrocería/Siniestros | E17: =COUNTIF(Registro_OT!$H$2:$H$181, C17) -> 9 | F17: =COUNTIFS(Registro_OT!$H$2:$H$181, C17, Registro_OT!$D$2:$D$181, "Preventivo") -> 0 | G17: =COUNTIFS(Registro_OT!$H$2:$H$181, C17, Registro_OT!$D$2:$D$181, "Correctivo/Falla") -> 0 | H17: =COUNTIFS(Registro_OT!$H$2:$H$181, C17, Registro_OT!$D$2:$D$181, "Siniestro/Carrocería") -> 9 | I17: =SUMIF(Registro_OT!$H$2:$H$181, C17, Registro_OT!$T$2:$T$181) -> 10847760 | J17: =SUMIF(Registro_OT!$H$2:$H$181, C17, Registro_OT!$AA$2:$AA$181) -> 3649520 | K17: =IF($J$21>0, J17/$J$21, 0) -> 0.1089596
B18: =Maestro_Tecnicos!A7 -> TEC-06 | C18: =Maestro_Tecnicos!B7 -> Daniela Mora | D18: =Maestro_Tecnicos!C7 -> Carrocería/Siniestros | E18: =COUNTIF(Registro_OT!$H$2:$H$181, C18) -> 17 | F18: =COUNTIFS(Registro_OT!$H$2:$H$181, C18, Registro_OT!$D$2:$D$181, "Preventivo") -> 0 | G18: =COUNTIFS(Registro_OT!$H$2:$H$181, C18, Registro_OT!$D$2:$D$181, "Correctivo/Falla") -> 0 | H18: =COUNTIFS(Registro_OT!$H$2:$H$181, C18, Registro_OT!$D$2:$D$181, "Siniestro/Carrocería") -> 17 | I18: =SUMIF(Registro_OT!$H$2:$H$181, C18, Registro_OT!$T$2:$T$181) -> 18254500 | J18: =SUMIF(Registro_OT!$H$2:$H$181, C18, Registro_OT!$AA$2:$AA$181) -> 8062860 | K18: =IF($J$21>0, J18/$J$21, 0) -> 0.24072371
B19: =Maestro_Tecnicos!A8 -> TEC-07 | C19: =Maestro_Tecnicos!B8 -> Héctor Pizarro | D19: =Maestro_Tecnicos!C8 -> Electricidad | E19: =COUNTIF(Registro_OT!$H$2:$H$181, C19) -> 10 | F19: =COUNTIFS(Registro_OT!$H$2:$H$181, C19, Registro_OT!$D$2:$D$181, "Preventivo") -> 3 | G19: =COUNTIFS(Registro_OT!$H$2:$H$181, C19, Registro_OT!$D$2:$D$181, "Correctivo/Falla") -> 0 | H19: =COUNTIFS(Registro_OT!$H$2:$H$181, C19, Registro_OT!$D$2:$D$181, "Siniestro/Carrocería") -> 0 | I19: =SUMIF(Registro_OT!$H$2:$H$181, C19, Registro_OT!$T$2:$T$181) -> 5105890 | J19: =SUMIF(Registro_OT!$H$2:$H$181, C19, Registro_OT!$AA$2:$AA$181) -> 1619300 | K19: =IF($J$21>0, J19/$J$21, 0) -> 0.048345612
B20: =Maestro_Tecnicos!A9 -> TEC-08 | C20: =Maestro_Tecnicos!B9 -> Andrea Salinas | D20: =Maestro_Tecnicos!C9 -> Electricidad | E20: =COUNTIF(Registro_OT!$H$2:$H$181, C20) -> 13 | F20: =COUNTIFS(Registro_OT!$H$2:$H$181, C20, Registro_OT!$D$2:$D$181, "Preventivo") -> 8 | G20: =COUNTIFS(Registro_OT!$H$2:$H$181, C20, Registro_OT!$D$2:$D$181, "Correctivo/Falla") -> 0 | H20: =COUNTIFS(Registro_OT!$H$2:$H$181, C20, Registro_OT!$D$2:$D$181, "Siniestro/Carrocería") -> 0 | I20: =SUMIF(Registro_OT!$H$2:$H$181, C20, Registro_OT!$T$2:$T$181) -> 4755850 | J20: =SUMIF(Registro_OT!$H$2:$H$181, C20, Registro_OT!$AA$2:$AA$181) -> 1769840 | K20: =IF($J$21>0, J20/$J$21, 0) -> 0.052840114
C21: TOTALES TALLER | E21: =SUM(E13:E20) -> 180 | F21: =SUM(F13:F20) -> 76 | G21: =SUM(G13:G20) -> 0 | H21: =SUM(H13:H20) -> 41 | I21: =SUM(I13:I20) -> 93641900 | J21: =SUM(J13:J20) -> 33494250 | K21: =SUM(K13:K20) -> 1

Sheet Dashboard_Graficos
B1: DASHBOARD VISUAL DE GRÁFICOS · APORTE POR MECÁNICO Y EVOLUCIÓN MENSUAL
B2: Representación gráfica de la participación de facturación por mecánico y tendencia mensual de trabajo
B4: 1. FACTURACIÓN MENSUAL TOTAL ($)
B5: Mes | C5: Monto Facturado ($)
B6: 2026-05 | C6: =SUMIF(Registro_OT!$AD$2:$AD$181, "2026-05", Registro_OT!$T$2:$T$181) -> 14788190
B7: 2026-06 | C7: =SUMIF(Registro_OT!$AD$2:$AD$181, "2026-06", Registro_OT!$T$2:$T$181) -> 11815630
B8: 2026-07 | C8: =SUMIF(Registro_OT!$AD$2:$AD$181, "2026-07", Registro_OT!$T$2:$T$181) -> 20371780
B9: 2026-08 | C9: =SUMIF(Registro_OT!$AD$2:$AD$181, "2026-08", Registro_OT!$T$2:$T$181) -> 19596030
B10: 2026-09 | C10: =SUMIF(Registro_OT!$AD$2:$AD$181, "2026-09", Registro_OT!$T$2:$T$181) -> 21306950
B11: 2026-10 | C11: =SUMIF(Registro_OT!$AD$2:$AD$181, "2026-10", Registro_OT!$T$2:$T$181) -> 5763320
B14: 2. APORTE DE FACTURACIÓN POR MECÁNICO
B15: Mecánico | C15: Monto Facturado ($)
B16: =Maestro_Tecnicos!B2 -> Marcelo Fuentes | C16: =SUMIF(Registro_OT!$H$2:$H$181, B16, Registro_OT!$T$2:$T$181) -> 16388220
B17: =Maestro_Tecnicos!B3 -> Cristian Araya | C17: =SUMIF(Registro_OT!$H$2:$H$181, B17, Registro_OT!$T$2:$T$181) -> 14376150
B18: =Maestro_Tecnicos!B4 -> Luis Contreras | C18: =SUMIF(Registro_OT!$H$2:$H$181, B18, Registro_OT!$T$2:$T$181) -> 13057260
B19: =Maestro_Tecnicos!B5 -> Patricio Rojas | C19: =SUMIF(Registro_OT!$H$2:$H$181, B19, Registro_OT!$T$2:$T$181) -> 10856270
B20: =Maestro_Tecnicos!B6 -> Sergio Valdés | C20: =SUMIF(Registro_OT!$H$2:$H$181, B20, Registro_OT!$T$2:$T$181) -> 10847760
B21: =Maestro_Tecnicos!B7 -> Daniela Mora | C21: =SUMIF(Registro_OT!$H$2:$H$181, B21, Registro_OT!$T$2:$T$181) -> 18254500
B22: =Maestro_Tecnicos!B8 -> Héctor Pizarro | C22: =SUMIF(Registro_OT!$H$2:$H$181, B22, Registro_OT!$T$2:$T$181) -> 5105890
B23: =Maestro_Tecnicos!B9 -> Andrea Salinas | C23: =SUMIF(Registro_OT!$H$2:$H$181, B23, Registro_OT!$T$2:$T$181) -> 4755850

Sheet Maestro_Clientes
A1: ID_Cliente | B1: Nombre_Cliente | C1: Categoria | D1: Contacto
A2: CLI-001 | B2: Buses Cordillera Ltda. | C2: Empresa de Transporte | D2: Rodrigo Silva · contacto1@ejemplo.cl · +56 9 5555 0100
A3: CLI-002 | B3: Transportes Maipo SpA | C3: Empresa de Transporte | D3: Carolina Vera · contacto2@ejemplo.cl · +56 9 5555 0101
A4: CLI-003 | B4: Línea Los Pinos S.A. | C4: Empresa de Transporte | D4: Miguel Ortiz · contacto3@ejemplo.cl · +56 9 5555 0102
A5: CLI-004 | B5: Expreso Lo Espejo | C5: Empresa de Transporte | D5: Paula Herrera · contacto4@ejemplo.cl · +56 9 5555 0103
A6: CLI-005 | B6: Buses Rapel SpA | C6: Empresa de Transporte | D6: Andrés Lagos · contacto5@ejemplo.cl · +56 9 5555 0104
A7: CLI-006 | B7: Transportes Pacífico Sur | C7: Empresa de Transporte | D7: Marcela Pino · contacto6@ejemplo.cl · +56 9 5555 0105
A8: CLI-007 | B8: Inversiones Alto Jahuel | C8: Empresa de Transporte | D8: Felipe Cárdenas · contacto7@ejemplo.cl · +56 9 5555 0106
A9: CLI-008 | B9: Turismo Andes Sur | C9: Empresa de Transporte | D9: Verónica Toro · contacto8@ejemplo.cl · +56 9 5555 0107
A10: CLI-009 | B10: Buses Costa Verde Ltda. | C10: Empresa de Transporte | D10: Ignacio Bravo · contacto9@ejemplo.cl · +56 9 5555 0108
A11: CLI-010 | B11: Municipalidad Valle Norte | C11: Municipal | D11: Sandra Leiva · contacto10@ejemplo.cl · +56 9 5555 0109
A12: CLI-011 | B12: Municipalidad Costa Sur | C12: Municipal | D12: Hugo Navarro · contacto11@ejemplo.cl · +56 9 5555 0110
... A19: CLI-018 | B19: Cooperativa Agrícola El Maitén | C19: Particular | D19: Nancy Soto · contacto18@ejemplo.cl · +56 9 5555 0117

Sheet Maestro_Tecnicos
A1: ID_Tecnico | B1: Nombre_Tecnico | C1: Especialidad
A2: TEC-01 | B2: Marcelo Fuentes | C2: Mecánica General
A3: TEC-02 | B3: Cristian Araya | C3: Mecánica General
A4: TEC-03 | B4: Luis Contreras | C4: Mecánica General
A5: TEC-04 | B5: Patricio Rojas | C5: Carrocería/Siniestros
A6: TEC-05 | B6: Sergio Valdés | C6: Carrocería/Siniestros
A7: TEC-06 | B7: Daniela Mora | C7: Carrocería/Siniestros
A8: TEC-07 | B8: Héctor Pizarro | C8: Electricidad
A9: TEC-08 | B9: Andrea Salinas | C9: Electricidad

Sheet Maestro_Repuestos
A1: ID_Repuesto | B1: Descripcion_Repuesto | C1: Categoria | D1: Costo_Unitario_Referencia | E1: Unidad_Medida | F1: Cantidad_Usada | G1: Costo_Consumo | H1: Rank_Cantidad | I1: Rank_Costo
A2: REP-001 | B2: Filtro de aceite motor diésel | C2: Filtros/Aceites | D2: 14500 | E2: Unidad | F2: =SUMIFS(T_DetalleOT[Cantidad_o_Horas],T_DetalleOT[ID_Repuesto_o_Tecnico],A2,T_DetalleOT[En_Filtro],1) -> 54 | G2: =SUMIFS(T_DetalleOT[Costo_Total],T_DetalleOT[ID_Repuesto_o_Tecnico],A2,T_DetalleOT[En_Filtro],1) -> 775980 | H2: =RANK(F2,$F$2:$F$25,0)+COUNTIF($F$2:F2,F2)-1 -> 6 | I2: =RANK(G2,$G$2:$G$25,0)+COUNTIF($G$2:G2,G2)-1 -> 18
A3: REP-002 | B3: Filtro de aire | C3: Filtros/Aceites | D3: 28900 | E3: Unidad | F3: =SUMIFS(T_DetalleOT[Cantidad_o_Horas],T_DetalleOT[ID_Repuesto_o_Tecnico],A3,T_DetalleOT[En_Filtro],1) -> 53 | G3: =SUMIFS(T_DetalleOT[Costo_Total],T_DetalleOT[ID_Repuesto_o_Tecnico],A3,T_DetalleOT[En_Filtro],1) -> 1602300 | H3: =RANK(F3,$F$2:$F$25,0)+COUNTIF($F$2:F3,F3)-1 -> 7 | I3: =RANK(G3,$G$2:$G$25,0)+COUNTIF($G$2:G3,G3)-1 -> 12
A4: REP-003 | B4: Filtro de combustible | C4: Filtros/Aceites | D4: 21900 | E4: Unidad | F4: =SUMIFS(T_DetalleOT[Cantidad_o_Horas],T_DetalleOT[ID_Repuesto_o_Tecnico],A4,T_DetalleOT[En_Filtro],1) -> 62 | G4: =SUMIFS(T_DetalleOT[Costo_Total],T_DetalleOT[ID_Repuesto_o_Tecnico],A4,T_DetalleOT[En_Filtro],1) -> 1355460 | H4: =RANK(F4,$F$2:$F$25,0)+COUNTIF($F$2:F4,F4)-1 -> 5 | I4: =RANK(G4,$G$2:$G$25,0)+COUNTIF($G$2:G4,G4)-1 -> 15
A5: REP-004 | B5: Aceite motor 15W40 | C5: Filtros/Aceites | D5: 5200 | E5: Litro | F5: =SUMIFS(T_DetalleOT[Cantidad_o_Horas],T_DetalleOT[ID_Repuesto_o_Tecnico],A5,T_DetalleOT[En_Filtro],1) -> 276 | G5: =SUMIFS(T_DetalleOT[Costo_Total],T_DetalleOT[ID_Repuesto_o_Tecnico],A5,T_DetalleOT[En_Filtro],1) -> 1394070 | H5: =RANK(F5,$F$2:$F$25,0)+COUNTIF($F$2:F5,F5)-1 -> 3 | I5: =RANK(G5,$G$2:$G$25,0)+COUNTIF($G$2:G5,G5)-1 -> 14
A6: REP-005 | B6: Aceite de caja 80W90 | C6: Filtros/Aceites | D6: 6100 | E6: Litro | F6: =SUMIFS(T_DetalleOT[Cantidad_o_Horas],T_DetalleOT[ID_Repuesto_o_Tecnico],A6,T_DetalleOT[En_Filtro],1) -> 415 | G6: =SUMIFS(T_DetalleOT[Costo_Total],T_DetalleOT[ID_Repuesto_o_Tecnico],A6,T_DetalleOT[En_Filtro],1) -> 2648980 | H6: =RANK(F6,$F$2:$F$25,0)+COUNTIF($F$2:F6,F6)-1 -> 1 | I6: =RANK(G6,$G$2:$G$25,0)+COUNTIF($G$2:G6,G6)-1 -> 5
A7: REP-006 | B7: Refrigerante concentrado | C7: Filtros/Aceites | D7: 4300 | E7: Litro | F7: =SUMIFS(T_DetalleOT[Cantidad_o_Horas],T_DetalleOT[ID_Repuesto_o_Tecnico],A7,T_DetalleOT[En_Filtro],1) -> 352 | G7: =SUMIFS(T_DetalleOT[Costo_Total],T_DetalleOT[ID_Repuesto_o_Tecnico],A7,T_DetalleOT[En_Filtro],1) -> 1545540 | H7: =RANK(F7,$F$2:$F$25,0)+COUNTIF($F$2:F7,F7)-1 -> 2 | I7: =RANK(G7,$G$2:$G$25,0)+COUNTIF($G$2:G7,G7)-1 -> 13
A8: REP-007 | B8: Parabrisas panorámico | C8: Cristales/Espejos | D8: 385000 | E8: Unidad | F8: =SUMIFS(T_DetalleOT[Cantidad_o_Horas],T_DetalleOT[ID_Repuesto_o_Tecnico],A8,T_DetalleOT[En_Filtro],1) -> 17 | G8: =SUMIFS(T_DetalleOT[Costo_Total],T_DetalleOT[ID_Repuesto_o_Tecnico],A8,T_DetalleOT[En_Filtro],1) -> 6765540 | H8: =RANK(F8,$F$2:$F$25,0)+COUNTIF($F$2:F8,F8)-1 -> 17 | I8: =RANK(G8,$G$2:$G$25,0)+COUNTIF($G$2:G8,G8)-1 -> 1
A9: REP-008 | B9: Ventana lateral templada | C9: Cristales/Espejos | D9: 96000 | E9: Unidad | F9: =SUMIFS(T_DetalleOT[Cantidad_o_Horas],T_DetalleOT[ID_Repuesto_o_Tecnico],A9,T_DetalleOT[En_Filtro],1) -> 20 | G9: =SUMIFS(T_DetalleOT[Costo_Total],T_DetalleOT[ID_Repuesto_o_Tecnico],A9,T_DetalleOT[En_Filtro],1) -> 2102050 | H9: =RANK(F9,$F$2:$F$25,0)+COUNTIF($F$2:F9,F9)-1 -> 14 | I9: =RANK(G9,$G$2:$G$25,0)+COUNTIF($G$2:G9,G9)-1 -> 11
A10: REP-009 | B10: Espejo retrovisor exterior | C10: Cristales/Espejos | D10: 78000 | E10: Unidad | F10: =SUMIFS(T_DetalleOT[Cantidad_o_Horas],T_DetalleOT[ID_Repuesto_o_Tecnico],A10,T_DetalleOT[En_Filtro],1) -> 12 | G10: =SUMIFS(T_DetalleOT[Costo_Total],T_DetalleOT[ID_Repuesto_o_Tecnico],A10,T_DetalleOT[En_Filtro],1) -> 1000300 | H10: =RANK(F10,$F$2:$F$25,0)+COUNTIF($F$2:F10,F10)-1 -> 23 | I10: =RANK(G10,$G$2:$G$25,0)+COUNTIF($G$2:G10,G10)-1 -> 16
A11: REP-010 | B11: Espejo interior panorámico | C11: Cristales/Espejos | D11: 32000 | E11: Unidad | F11: =SUMIFS(T_DetalleOT[Cantidad_o_Horas],T_DetalleOT[ID_Repuesto_o_Tecnico],A11,T_DetalleOT[En_Filtro],1) -> 14 | G11: =SUMIFS(T_DetalleOT[Costo_Total],T_DetalleOT[ID_Repuesto_o_Tecnico],A11,T_DetalleOT[En_Filtro],1) -> 467500 | H11: =RANK(F11,$F$2:$F$25,0)+COUNTIF($F$2:F11,F11)-1 -> 20 | I11: =RANK(G11,$G$2:$G$25,0)+COUNTIF($G$2:G11,G11)-1 -> 22
A12: REP-011 | B12: Luneta trasera | C12: Cristales/Espejos | D12: 210000 | E12: Unidad | F12: =SUMIFS(T_DetalleOT[Cantidad_o_Horas],T_DetalleOT[ID_Repuesto_o_Tecnico],A12,T_DetalleOT[En_Filtro],1) -> 13 | G12: =SUMIFS(T_DetalleOT[Costo_Total],T_DetalleOT[ID_Repuesto_o_Tecnico],A12,T_DetalleOT[En_Filtro],1) -> 2767420 | H12: =RANK(F12,$F$2:$F$25,0)+COUNTIF($F$2:F12,F12)-1 -> 21 | I12: =RANK(G12,$G$2:$G$25,0)+COUNTIF($G$2:G12,G12)-1 -> 4
A13: REP-012 | B13: Kit sello de cristal | C13: Cristales/Espejos | D13: 18500 | E13: Juego | F13: =SUMIFS(T_DetalleOT[Cantidad_o_Horas],T_DetalleOT[ID_Repuesto_o_Tecnico],A13,T_DetalleOT[En_Filtro],1) -> 17 | G13: =SUMIFS(T_DetalleOT[Costo_Total],T_DetalleOT[ID_Repuesto_o_Tecnico],A13,T_DetalleOT[En_Filtro],1) -> 339320 | H13: =RANK(F13,$F$2:$F$25,0)+COUNTIF($F$2:F13,F13)-1 -> 18 | I13: =RANK(G13,$G$2:$G$25,0)+COUNTIF($G$2:G13,G13)-1 -> 23
... A25: REP-024 | B25: Kit pernos U de ballesta | C25: Suspensión | D25: 22500 | E25: Juego | F25: =SUMIFS(T_DetalleOT[Cantidad_o_Horas],T_DetalleOT[ID_Repuesto_o_Tecnico],A25,T_DetalleOT[En_Filtro],1) -> 30 | G25: =SUMIFS(T_DetalleOT[Costo_Total],T_DetalleOT[ID_Repuesto_o_Tecnico],A25,T_DetalleOT[En_Filtro],1) -> 690080 | H25: =RANK(F25,$F$2:$F$25,0)+COUNTIF($F$2:F25,F25)-1 -> 12 | I25: =RANK(G25,$G$2:$G$25,0)+COUNTIF($G$2:G25,G25)-1 -> 19

Sheet Registro_OT
A1: ID_OT | B1: ID_Cliente | C1: Patente_Bus | D1: Tipo_Servicio | E1: Fecha_Ingreso | F1: Fecha_Compromiso | G1: Fecha_Termino | H1: Responsable_OT | I1: Estado_OT | J1: ID_Presupuesto | K1: Fecha_Presupuesto | L1: Monto_Presupuesto | M1: Estado_Presupuesto | N1: ID_OC | O1: Fecha_OC | P1: Monto_OC | Q1: Estado_OC | R1: ID_Factura | S1: Fecha_Factura | T1: Monto_Facturado | U1: Monto_Pagado | V1: Saldo_Pendiente | W1: Estado_Cuadre_3Way | X1: Monto_Total_Cobrable | Y1: Costo_Materiales | Z1: Costo_Mano_Obra | AA1: Margen | AB1: Margen_Pct | AC1: Estado_Economico | AD1: Mes_Ingreso | AE1: Semana_Ingreso | AF1: Dias_en_Taller | AG1: Cumple_Plazo | AH1: Atrasada_Activa | AI1: Pend_OC | AJ1: Pend_Facturacion | AK1: Dato_Incompleto | AL1: En_Filtro | AM1: En_Filtro_Mandante | AN1: Seq_Atrasada | AO1: Seq_Pend_Fact | AP1: Seq_Incompleta
A2: OT-0001 | B2: CLI-015 | C2: XSLT-12 | D2: Preventivo | E2: 46143 | F2: 46147 | G2: 46147 | H2: Luis Contreras | I2: Entregada | J2: PRES-1001 | K2: 46143 | L2: =X2 -> 243920 | M2: Aprobado | N2: OC-5001 | O2: 46144 | P2: =X2 -> 243920 | Q2: Recibida | R2: FACT-3001 | S2: 46149 | T2: =X2 -> 243920 | U2: =T2 -> 243920 | V2: =IF(R2<>"", T2-U2, 0) -> 0 | W2: =IF(OR(M2="Pendiente", M2="Rechazado"), "Presupuesto No Aprobado", IF(N2="", "Falta OC Mandante", IF(R2="", "OC Recibida - Pendiente Factura", IF(AND(L2=P2, P2=T2), "CUADRADO (3-WAY OK)", "DESCUADRE DE MONTOS")))) -> CUADRADO (3-WAY OK) | X2: =SUMIFS(Detalle_OT!$I$2:$I$592,Detalle_OT!$B$2:$B$592,A2) -> 243920 | Y2: =SUMIFS(Detalle_OT!$H$2:$H$592,Detalle_OT!$B$2:$B$592,A2,Detalle_OT!$C$2:$C$592,"Repuesto") -> 113040 | Z2: =SUMIFS(Detalle_OT!$H$2:$H$592,Detalle_OT!$B$2:$B$592,A2,Detalle_OT!$C$2:$C$592,"Mano de Obra") -> 46800 | AA2: =IF(AK2=1, "", X2-Y2-Z2) -> 84080 | AB2: =IF(OR(AK2=1, X2=0, ISBLANK(X2)), "", AA2/X2) -> 0.34470318 | AC2: =IF(AK2=1, "Pendiente de Validación", IF(AA2<0, "Margen Negativo Confirmado", "Margen No Negativo Confirmado")) -> Margen No Negativo Confirmado | AD2: =YEAR(E2)&"-"&TEXT(MONTH(E2),"00") -> 2026-05 | AE2: ="Semana "&WEEKNUM(E2) -> Semana 18 | AF2: =IF(G2<>"", G2-E2, "") -> 4 | AG2: =IF(G2="","",IF(G2<=F2,1,0)) -> 1 | AH2: =IF(AND(G2="",OR(I2="En Curso",I2="Reprogramada"),F2<Dashboard!$B$5),1,0) -> 0 | AI2: =IF(AND(M2="Aprobado", N2=""), 1, 0) -> 0 | AJ2: =IF(AND(OR(I2="Terminada",I2="Entregada"), R2=""), 1, 0) -> 0 | AK2: =IF(SUMIFS(Detalle_OT!$J$2:$J$592,Detalle_OT!$B$2:$B$592,A2)>0,1,0) -> 0 | AL2: =IF(AND(OR(Dashboard!$D$5="Todos",AD2=Dashboard!$D$5),OR(Dashboard!$F$5="Todos",D2=Dashboard!$F$5),OR(Dashboard!$H$5="Todos",I2=Dashboard!$H$5)),1,0) -> 1 | AM2: =IF(AND(OR(Control_Mandante!$C$4="Todos", AD2=Control_Mandante!$C$4), OR(Control_Mandante!$F$4="Todos", B2=Control_Mandante!$F$4), OR(Control_Mandante!$I$4="Todos", W2=Control_Mandante!$I$4), OR(Control_Mandante!$L$4="Todos", H2=Control_Mandante!$L$4)), 1, 0) -> 1 | AN2: =IF(AH2=1, COUNTIF(AH$2:AH2, 1), "") | AO2: =IF(AJ2=1, COUNTIF(AJ$2:AJ2, 1), "") | AP2: =IF(AK2=1, COUNTIF(AK$2:AK2, 1), "")
A3: OT-0002 | B3: CLI-015 | C3: SKWX-95 | D3: Preventivo | E3: 46146 | F3: 46148 | G3: 46157 | H3: Marcelo Fuentes | I3: Entregada | J3: PRES-1002 | K3: 46146 | L3: =X3 -> 215570 | M3: Aprobado | N3: OC-5002 | O3: 46147 | P3: =X3 -> 215570 | Q3: Recibida | R3: FACT-3002 | S3: 46159 | T3: =X3 -> 215570 | U3: =T3 -> 215570 | V3: =IF(R3<>"", T3-U3, 0) -> 0 | W3: =IF(OR(M3="Pendiente", M3="Rechazado"), "Presupuesto No Aprobado", IF(N3="", "Falta OC Mandante", IF(R3="", "OC Recibida - Pendiente Factura", IF(AND(L3=P3, P3=T3), "CUADRADO (3-WAY OK)", "DESCUADRE DE MONTOS")))) -> CUADRADO (3-WAY OK) | X3: =SUMIFS(Detalle_OT!$I$2:$I$592,Detalle_OT!$B$2:$B$592,A3) -> 215570 | Y3: =SUMIFS(Detalle_OT!$H$2:$H$592,Detalle_OT!$B$2:$B$592,A3,Detalle_OT!$C$2:$C$592,"Repuesto") -> 94290 | Z3: =SUMIFS(Detalle_OT!$H$2:$H$592,Detalle_OT!$B$2:$B$592,A3,Detalle_OT!$C$2:$C$592,"Mano de Obra") -> 51600 | AA3: =IF(AK3=1, "", X3-Y3-Z3) -> 69680 | AB3: =IF(OR(AK3=1, X3=0, ISBLANK(X3)), "", AA3/X3) -> 0.32323607 | AC3: =IF(AK3=1, "Pendiente de Validación", IF(AA3<0, "Margen Negativo Confirmado", "Margen No Negativo Confirmado")) -> Margen No Negativo Confirmado | AD3: =YEAR(E3)&"-"&TEXT(MONTH(E3),"00") -> 2026-05 | AE3: ="Semana "&WEEKNUM(E3) -> Semana 19 | AF3: =IF(G3<>"", G3-E3, "") -> 11 | AG3: =IF(G3="","",IF(G3<=F3,1,0)) -> 0 | AH3: =IF(AND(G3="",OR(I3="En Curso",I3="Reprogramada"),F3<Dashboard!$B$5),1,0) -> 0 | AI3: =IF(AND(M3="Aprobado", N3=""), 1, 0) -> 0 | AJ3: =IF(AND(OR(I3="Terminada",I3="Entregada"), R3=""), 1, 0) -> 0 | AK3: =IF(SUMIFS(Detalle_OT!$J$2:$J$592,Detalle_OT!$B$2:$B$592,A3)>0,1,0) -> 0 | AL3: =IF(AND(OR(Dashboard!$D$5="Todos",AD3=Dashboard!$D$5),OR(Dashboard!$F$5="Todos",D3=Dashboard!$F$5),OR(Dashboard!$H$5="Todos",I3=Dashboard!$H$5)),1,0) -> 1 | AM3: =IF(AND(OR(Control_Mandante!$C$4="Todos", AD3=Control_Mandante!$C$4), OR(Control_Mandante!$F$4="Todos", B3=Control_Mandante!$F$4), OR(Control_Mandante!$I$4="Todos", W3=Control_Mandante!$I$4), OR(Control_Mandante!$L$4="Todos", H3=Control_Mandante!$L$4)), 1, 0) -> 1 | AN3: =IF(AH3=1, COUNTIF(AH$2:AH3, 1), "") | AO3: =IF(AJ3=1, COUNTIF(AJ$2:AJ3, 1), "") | AP3: =IF(AK3=1, COUNTIF(AK$2:AK3, 1), "")
A4: OT-0003 | B4: CLI-009 | C4: RCYD-42 | D4: Preventivo | E4: 46146 | F4: 46149 | G4: 46149 | H4: Luis Contreras | I4: Terminada | J4: PRES-1003 | K4: 46146 | L4: =X4 -> 168410 | M4: Aprobado | N4: OC-5003 | O4: 46147 | P4: =X4 -> 168410 | Q4: Recibida | T4: 0 | U4: 0 | V4: =IF(R4<>"", T4-U4, 0) -> 0 | W4: =IF(OR(M4="Pendiente", M4="Rechazado"), "Presupuesto No Aprobado", IF(N4="", "Falta OC Mandante", IF(R4="", "OC Recibida - Pendiente Factura", IF(AND(L4=P4, P4=T4), "CUADRADO (3-WAY OK)", "DESCUADRE DE MONTOS")))) -> OC Recibida - Pendiente Factura | X4: =SUMIFS(Detalle_OT!$I$2:$I$592,Detalle_OT!$B$2:$B$592,A4) -> 168410 | Y4: =SUMIFS(Detalle_OT!$H$2:$H$592,Detalle_OT!$B$2:$B$592,A4,Detalle_OT!$C$2:$C$592,"Repuesto") -> 92150 | Z4: =SUMIFS(Detalle_OT!$H$2:$H$592,Detalle_OT!$B$2:$B$592,A4,Detalle_OT!$C$2:$C$592,"Mano de Obra") -> 27200 | AA4: =IF(AK4=1, "", X4-Y4-Z4) -> 49060 | AB4: =IF(OR(AK4=1, X4=0, ISBLANK(X4)), "", AA4/X4) -> 0.29131287 | AC4: =IF(AK4=1, "Pendiente de Validación", IF(AA4<0, "Margen Negativo Confirmado", "Margen No Negativo Confirmado")) -> Margen No Negativo Confirmado | AD4: =YEAR(E4)&"-"&TEXT(MONTH(E4),"00") -> 2026-05 | AE4: ="Semana "&WEEKNUM(E4) -> Semana 19 | AF4: =IF(G4<>"", G4-E4, "") -> 3 | AG4: =IF(G4="","",IF(G4<=F4,1,0)) -> 1 | AH4: =IF(AND(G4="",OR(I4="En Curso",I4="Reprogramada"),F4<Dashboard!$B$5),1,0) -> 0 | AI4: =IF(AND(M4="Aprobado", N4=""), 1, 0) -> 0 | AJ4: =IF(AND(OR(I4="Terminada",I4="Entregada"), R4=""), 1, 0) -> 1 | AK4: =IF(SUMIFS(Detalle_OT!$J$2:$J$592,Detalle_OT!$B$2:$B$592,A4)>0,1,0) -> 0 | AL4: =IF(AND(OR(Dashboard!$D$5="Todos",AD4=Dashboard!$D$5),OR(Dashboard!$F$5="Todos",D4=Dashboard!$F$5),OR(Dashboard!$H$5="Todos",I4=Dashboard!$H$5)),1,0) -> 1 | AM4: =IF(AND(OR(Control_Mandante!$C$4="Todos", AD4=Control_Mandante!$C$4), OR(Control_Mandante!$F$4="Todos", B4=Control_Mandante!$F$4), OR(Control_Mandante!$I$4="Todos", W4=Control_Mandante!$I$4), OR(Control_Mandante!$L$4="Todos", H4=Control_Mandante!$L$4)), 1, 0) -> 1 | AN4: =IF(AH4=1, COUNTIF(AH$2:AH4, 1), "") | AO4: =IF(AJ4=1, COUNTIF(AJ$2:AJ4, 1), "") -> 1 | AP4: =IF(AK4=1, COUNTIF(AK$2:AK4, 1), "")
A5: OT-0004 | B5: CLI-009 | C5: KZJV-65 | D5: Siniestro/Carrocería | E5: 46149 | F5: 46161 | G5: 46161 | H5: Daniela Mora | I5: Entregada | J5: PRES-1004 | K5: 46149 | L5: =X5 -> 971280 | M5: Aprobado | N5: OC-5004 | O5: 46150 | P5: =X5 -> 971280 | Q5: Recibida | R5: FACT-3004 | S5: 46163 | T5: =X5 -> 971280 | U5: =T5 -> 971280 | V5: =IF(R5<>"", T5-U5, 0) -> 0 | W5: =IF(OR(M5="Pendiente", M5="Rechazado"), "Presupuesto No Aprobado", IF(N5="", "Falta OC Mandante", IF(R5="", "OC Recibida - Pendiente Factura", IF(AND(L5=P5, P5=T5), "CUADRADO (3-WAY OK)", "DESCUADRE DE MONTOS")))) -> CUADRADO (3-WAY OK) | X5: =SUMIFS(Detalle_OT!$I$2:$I$592,Detalle_OT!$B$2:$B$592,A5) -> 971280 | Y5: =SUMIFS(Detalle_OT!$H$2:$H$592,Detalle_OT!$B$2:$B$592,A5,Detalle_OT!$C$2:$C$592,"Repuesto") -> 376360 | Z5: =SUMIFS(Detalle_OT!$H$2:$H$592,Detalle_OT!$B$2:$B$592,A5,Detalle_OT!$C$2:$C$592,"Mano de Obra") -> 287700 | AA5: =IF(AK5=1, "", X5-Y5-Z5) -> 307220 | AB5: =IF(OR(AK5=1, X5=0, ISBLANK(X5)), "", AA5/X5) -> 0.31630426 | AC5: =IF(AK5=1, "Pendiente de Validación", IF(AA5<0, "Margen Negativo Confirmado", "Margen No Negativo Confirmado")) -> Margen No Negativo Confirmado | AD5: =YEAR(E5)&"-"&TEXT(MONTH(E5),"00") -> 2026-05 | AE5: ="Semana "&WEEKNUM(E5) -> Semana 19 | AF5: =IF(G5<>"", G5-E5, "") -> 12 | AG5: =IF(G5="","",IF(G5<=F5,1,0)) -> 1 | AH5: =IF(AND(G5="",OR(I5="En Curso",I5="Reprogramada"),F5<Dashboard!$B$5),1,0) -> 0 | AI5: =IF(AND(M5="Aprobado", N5=""), 1, 0) -> 0 | AJ5: =IF(AND(OR(I5="Terminada",I5="Entregada"), R5=""), 1, 0) -> 0 | AK5: =IF(SUMIFS(Detalle_OT!$J$2:$J$592,Detalle_OT!$B$2:$B$592,A5)>0,1,0) -> 0 | AL5: =IF(AND(OR(Dashboard!$D$5="Todos",AD5=Dashboard!$D$5),OR(Dashboard!$F$5="Todos",D5=Dashboard!$F$5),OR(Dashboard!$H$5="Todos",I5=Dashboard!$H$5)),1,0) -> 1 | AM5: =IF(AND(OR(Control_Mandante!$C$4="Todos", AD5=Control_Mandante!$C$4), OR(Control_Mandante!$F$4="Todos", B5=Control_Mandante!$F$4), OR(Control_Mandante!$I$4="Todos", W5=Control_Mandante!$I$4), OR(Control_Mandante!$L$4="Todos", H5=Control_Mandante!$L$4)), 1, 0) -> 1 | AN5: =IF(AH5=1, COUNTIF(AH$2:AH5, 1), "") | AO5: =IF(AJ5=1, COUNTIF(AJ$2:AJ5, 1), "") | AP5: =IF(AK5=1, COUNTIF(AK$2:AK5, 1), "")
